<?xml version="1.0" encoding="utf-8"?>
<robot name="ur5">
  <!-- world -->
  <link name="world"/>
  
  <joint name="ur5_pedestal_joint" type="fixed">
    <origin rpy="0 0 0" xyz="0.0 0.0 0.0"/>
    <parent link="world"/>
    <child link="ur5_pedestal_link"/>
  </joint>
  
  <link name="ur5_pedestal_link">
    <visual>
      <origin xyz="0 0 0.475"/>
      <geometry>
        <box size="0.3 0.3 0.95"/>
      </geometry>
      <material name="pedestal_color">
        <color rgba="0 0 0 1"/>
      </material>
    </visual>
    <collision>
      <origin xyz="0 0 0.475"/>
      <geometry>
        <box size="0.3 0.3 0.95"/>
      </geometry>
    </collision>
    <inertial>
      <mass value="500"/>
      <origin rpy="0 0 0" xyz="0 0 0"/>
      <inertia ixx="0.001" ixy="0" ixz="0" iyy="0.001" iyz="0" izz="0.001"/>
    </inertial>
  </link>

  <!-- robot2 to pedestal. -->
  <joint name="ur5_to_pedestal" type="fixed">
    <parent link="world"/>
    <child link="ur5_base_link"/>
    <origin rpy="0 0 0" xyz="0.0 0.0 0.95"/>
  </joint>
  
  <link name="ur5_base_link">
    <visual>
      <geometry>
        <cylinder length="0.12" radius="0.075"/>
      </geometry>
      <material name="LightGrey">
        <color rgba="0.7 0.7 0.7 1.0"/>
      </material>
    </visual>
    <collision>
      <geometry>
        <cylinder length="0.12" radius="0.075"/>
      </geometry>
    </collision>
    <inertial>
      <mass value="4.0"/>
      <origin rpy="0 0 0" xyz="0.0 0.0 0.0"/>
      <inertia ixx="0.00443333156" ixy="0.0" ixz="0.0" iyy="0.00443333156" iyz="0.0" izz="0.0072"/>
    </inertial>
  </link>

  <joint name="ur5_shoulder_pan_joint" type="revolute">
    <parent link="ur5_base_link"/>
    <child link="ur5_shoulder_link"/>
    <origin rpy="0.0 0.0 0.0" xyz="0.0 0.0 0.089159"/>
    <axis xyz="0 0 1"/>
    <limit effort="150.0" lower="-3.14159265359" upper="3.14159265359" velocity="3.15"/>
    <dynamics damping="0.0" friction="0.0"/>
  </joint>

  <!-- ROS base_link to UR 'Base' Coordinates transform -->
  <link name="ur5_base"/>
  <joint name="ur5_base_link-base_fixed_joint" type="fixed">
    <origin rpy="0 0 -3.14159265359" xyz="0 0 0"/>
    <parent link="ur5_base_link"/>
    <child link="ur5_base"/>
  </joint>

  <link name="ur5_shoulder_link">
    <visual>
      <geometry>
        <cylinder length="0.12" radius="0.075"/>
      </geometry>
      <material name="LightGrey">
        <color rgba="0.7 0.7 0.7 1.0"/>
      </material>
    </visual>
    <collision>
      <geometry>
        <cylinder length="0.12" radius="0.075"/>
      </geometry>
    </collision>
    <inertial>
      <mass value="3.7"/>
      <origin rpy="0 0 0" xyz="0.0 0.0 0.0"/>
      <inertia ixx="0.010267495893" ixy="0.0" ixz="0.0" iyy="0.010267495893" iyz="0.0" izz="0.00666"/>
    </inertial>
  </link>

  <joint name="ur5_shoulder_lift_joint" type="revolute">
    <parent link="ur5_shoulder_link"/>
    <child link="ur5_upper_arm_link"/>
    <origin rpy="0.0 1.57079632679 0.0" xyz="0.0 0.13585 0.0"/>
    <axis xyz="0 1 0"/>
    <limit effort="150.0" lower="-3.14159265359" upper="3.14159265359" velocity="3.15"/>
    <dynamics damping="0.0" friction="0.0"/>
  </joint>

  <link name="ur5_upper_arm_link">
    <visual>
      <geometry>
        <box size="0.425 0.1 0.1"/>
      </geometry>
      <origin rpy="0 0 0" xyz="0.2125 0 0"/>
      <material name="LightGrey">
        <color rgba="0.7 0.7 0.7 1.0"/>
      </material>
    </visual>
    <collision>
      <geometry>
        <box size="0.425 0.1 0.1"/>
      </geometry>
      <origin rpy="0 0 0" xyz="0.2125 0 0"/>
    </collision>
    <inertial>
      <mass value="8.393"/>
      <origin rpy="0 0 0" xyz="0.0 0.0 0.28"/>
      <inertia ixx="0.22689067591" ixy="0.0" ixz="0.0" iyy="0.22689067591" iyz="0.0" izz="0.0151074"/>
    </inertial>
  </link>

  <joint name="ur5_elbow_joint" type="revolute">
    <parent link="ur5_upper_arm_link"/>
    <child link="ur5_forearm_link"/>
    <origin rpy="0.0 0.0 0.0" xyz="0.0 -0.1197 0.425"/>
    <axis xyz="0 1 0"/>
    <limit effort="150.0" lower="-3.14159265359" upper="3.14159265359" velocity="3.15"/>
    <dynamics damping="0.0" friction="0.0"/>
  </joint>

  <link name="ur5_forearm_link">
    <visual>
      <geometry>
        <box size="0.39225 0.1 0.1"/>
      </geometry>
      <origin rpy="0 0 0" xyz="0.196125 0 0"/>
      <material name="LightGrey">
        <color rgba="0.7 0.7 0.7 1.0"/>
      </material>
    </visual>
    <collision>
      <geometry>
        <box size="0.39225 0.1 0.1"/>
      </geometry>
      <origin rpy="0 0 0" xyz="0.196125 0 0"/>
    </collision>
    <inertial>
      <mass value="2.275"/>
      <origin rpy="0 0 0" xyz="0.0 0.0 0.196125"/>
      <inertia ixx="0.0312167910289" ixy="0.0" ixz="0.0" iyy="0.0312167910289" iyz="0.0" izz="0.004095"/>
    </inertial>
  </link>

  <joint name="ur5_wrist_1_joint" type="revolute">
    <parent link="ur5_forearm_link"/>
    <child link="ur5_wrist_1_link"/>
    <origin rpy="0.0 1.57079632679 0.0" xyz="0.0 0.0 0.39225"/>
    <axis xyz="0 1 0"/>
    <limit effort="28.0" lower="-3.14159265359" upper="3.14159265359" velocity="3.2"/>
    <dynamics damping="0.0" friction="0.0"/>
  </joint>

  <link name="ur5_wrist_1_link">
    <visual>
      <geometry>
        <cylinder length="0.1" radius="0.06"/>
      </geometry>
      <material name="LightGrey">
        <color rgba="0.7 0.7 0.7 1.0"/>
      </material>
    </visual>
    <collision>
      <geometry>
        <cylinder length="0.1" radius="0.06"/>
      </geometry>
    </collision>
    <inertial>
      <mass value="1.219"/>
      <origin rpy="0 0 0" xyz="0.0 0.093 0.0"/>
      <inertia ixx="0.00255989897604" ixy="0.0" ixz="0.0" iyy="0.00255989897604" iyz="0.0" izz="0.0021942"/>
    </inertial>
  </link>

  <joint name="ur5_wrist_2_joint" type="revolute">
    <parent link="ur5_wrist_1_link"/>
    <child link="ur5_wrist_2_link"/>
    <origin rpy="0.0 0.0 0.0" xyz="0.0 0.093 0.0"/>
    <axis xyz="0 0 1"/>
    <limit effort="28.0" lower="-3.14159265359" upper="3.14159265359" velocity="3.2"/>
    <dynamics damping="0.0" friction="0.0"/>
  </joint>

  <link name="ur5_wrist_2_link">
    <visual>
      <geometry>
        <cylinder length="0.1" radius="0.06"/>
      </geometry>
      <material name="LightGrey">
        <color rgba="0.7 0.7 0.7 1.0"/>
      </material>
    </visual>
    <collision>
      <geometry>
        <cylinder length="0.1" radius="0.06"/>
      </geometry>
    </collision>
    <inertial>
      <mass value="1.219"/>
      <origin rpy="0 0 0" xyz="0.0 0.0 0.09465"/>
      <inertia ixx="0.00255989897604" ixy="0.0" ixz="0.0" iyy="0.00255989897604" iyz="0.0" izz="0.0021942"/>
    </inertial>
  </link>

  <joint name="ur5_wrist_3_joint" type="revolute">
    <parent link="ur5_wrist_2_link"/>
    <child link="ur5_wrist_3_link"/>
    <origin rpy="0.0 0.0 0.0" xyz="0.0 0.0 0.09465"/>
    <axis xyz="0 1 0"/>
    <limit effort="28.0" lower="-3.14159265359" upper="3.14159265359" velocity="3.2"/>
    <dynamics damping="0.0" friction="0.0"/>
  </joint>

  <link name="ur5_wrist_3_link">
    <visual>
      <geometry>
        <cylinder length="0.08" radius="0.045"/>
      </geometry>
      <material name="LightGrey">
        <color rgba="0.7 0.7 0.7 1.0"/>
      </material>
    </visual>
    <collision>
      <geometry>
        <cylinder length="0.08" radius="0.045"/>
      </geometry>
    </collision>
    <inertial>
      <mass value="0.1879"/>
      <origin rpy="1.57079632679 0 0" xyz="0.0 0.06505 0.0"/>
      <inertia ixx="8.46958911216e-05" ixy="0.0" ixz="0.0" iyy="8.46958911216e-05" iyz="0.0" izz="0.0001321171875"/>
    </inertial>
  </link>

  <joint name="ur5_ee_fixed_joint" type="fixed">
    <parent link="ur5_wrist_3_link"/>
    <child link="ur5_ee_link"/>
    <origin rpy="0.0 0.0 1.57079632679" xyz="0.0 0.0823 0.0"/>
  </joint>

  <link name="ur5_ee_link">
    <collision>
      <geometry>
        <box size="0.01 0.01 0.01"/>
      </geometry>
      <origin rpy="0 0 0" xyz="-0.01 0 0"/>
    </collision>
  </link>

  <!-- *** Gripper *** -->
  <joint name="ur5_wrist_3_link-tool0_fixed_joint" type="fixed">
    <origin rpy="-1.57079632679 0 0" xyz="0 0.0823 0"/>
    <parent link="ur5_wrist_3_link"/>
    <child link="ur5_tool0"/>
  </joint>

  <!-- Frame coincident with all-zeros TCP on UR controller -->
  <link name="ur5_tool0"/>

  <!-- gripper2 to robot2. -->
  <joint name="ur5_tool0_to_gripper_base" type="fixed">
    <parent link="ur5_tool0"/>
    <child link="Gripper_Base"/>
  </joint>

  <link name="Gripper_Base">
    <visual>
      <geometry>
        <cylinder length="0.022043" radius="0.067187"/>
      </geometry>
      <material name="blue">
        <color rgba="0 0 .8 1"/>
      </material>
    </visual>
    <collision>
      <geometry>
        <cylinder length="0.022043" radius="0.067187"/>
      </geometry>
    </collision>
    <inertial>
      <mass value="0.00001"/>
      <inertia ixx="0.14583300" ixy="0.00000000" ixz="0.0" iyy="0.14583300" iyz="0.0" izz="0.12500000"/>
    </inertial>
  </link>

  <joint name="gripper_base_to_gripper" type="revolute">
    <parent link="Gripper_Base" />
    <child link="vacuum_gripper_link" />
    <origin rpy="0 0 0" xyz="0 0 0.0221" />
    <limit effort="30" velocity="1.0" lower="0" upper="0" />
  </joint>

  <link name="vacuum_gripper_link">
    <visual>
      <geometry>
        <cylinder length="0.022043" radius="0.067187"/>
      </geometry>
      <material name="blue">
        <color rgba="0 0 .8 1"/>
      </material>
    </visual>
    <collision>
      <geometry>
        <cylinder length="0.022043" radius="0.067187"/>
      </geometry>
    </collision>
    <inertial>
      <mass value="0.00001"/>
      <inertia ixx="0.14583300" ixy="0.00000000" ixz="0.0" iyy="0.14583300" iyz="0.0" izz="0.12500000"/>
    </inertial>
  </link>

  <!-- Transmissions for ROS Control -->
  <transmission name="ur5_shoulder_pan_trans">
    <type>transmission_interface/SimpleTransmission</type>
    <joint name="ur5_shoulder_pan_joint">
      <hardwareInterface>hardware_interface/PositionJointInterface</hardwareInterface>
    </joint>
    <actuator name="ur5_shoulder_pan_motor">
      <hardwareInterface>hardware_interface/PositionJointInterface</hardwareInterface>
      <mechanicalReduction>1</mechanicalReduction>
    </actuator>
  </transmission>
  
  <transmission name="ur5_shoulder_lift_trans">
    <type>transmission_interface/SimpleTransmission</type>
    <joint name="ur5_shoulder_lift_joint">
      <hardwareInterface>hardware_interface/PositionJointInterface</hardwareInterface>
    </joint>
    <actuator name="ur5_shoulder_lift_motor">
      <hardwareInterface>hardware_interface/PositionJointInterface</hardwareInterface>
      <mechanicalReduction>1</mechanicalReduction>
    </actuator>
  </transmission>
  
  <transmission name="ur5_elbow_trans">
    <type>transmission_interface/SimpleTransmission</type>
    <joint name="ur5_elbow_joint">
      <hardwareInterface>hardware_interface/PositionJointInterface</hardwareInterface>
    </joint>
    <actuator name="ur5_elbow_motor">
      <hardwareInterface>hardware_interface/PositionJointInterface</hardwareInterface>
      <mechanicalReduction>1</mechanicalReduction>
    </actuator>
  </transmission>
  
  <transmission name="ur5_wrist_1_trans">
    <type>transmission_interface/SimpleTransmission</type>
    <joint name="ur5_wrist_1_joint">
      <hardwareInterface>hardware_interface/PositionJointInterface</hardwareInterface>
    </joint>
    <actuator name="ur5_wrist_1_motor">
      <hardwareInterface>hardware_interface/PositionJointInterface</hardwareInterface>
      <mechanicalReduction>1</mechanicalReduction>
    </actuator>
  </transmission>
  
  <transmission name="ur5_wrist_2_trans">
    <type>transmission_interface/SimpleTransmission</type>
    <joint name="ur5_wrist_2_joint">
      <hardwareInterface>hardware_interface/PositionJointInterface</hardwareInterface>
    </joint>
    <actuator name="ur5_wrist_2_motor">
      <hardwareInterface>hardware_interface/PositionJointInterface</hardwareInterface>
      <mechanicalReduction>1</mechanicalReduction>
    </actuator>
  </transmission>
  
  <transmission name="ur5_wrist_3_trans">
    <type>transmission_interface/SimpleTransmission</type>
    <joint name="ur5_wrist_3_joint">
      <hardwareInterface>hardware_interface/PositionJointInterface</hardwareInterface>
    </joint>
    <actuator name="ur5_wrist_3_motor">
      <hardwareInterface>hardware_interface/PositionJointInterface</hardwareInterface>
      <mechanicalReduction>1</mechanicalReduction>
    </actuator>
  </transmission>

  <!-- Gazebo specific elements, removed some plugins that might cause issues -->
  <gazebo reference="ur5_shoulder_link">
    <selfCollide>true</selfCollide>
  </gazebo>
  <gazebo reference="ur5_upper_arm_link">
    <selfCollide>true</selfCollide>
  </gazebo>
  <gazebo reference="ur5_forearm_link">
    <selfCollide>true</selfCollide>
  </gazebo>
  <gazebo reference="ur5_wrist_1_link">
    <selfCollide>true</selfCollide>
  </gazebo>
  <gazebo reference="ur5_wrist_3_link">
    <selfCollide>true</selfCollide>
  </gazebo>
  <gazebo reference="ur5_wrist_2_link">
    <selfCollide>true</selfCollide>
  </gazebo>
  <gazebo reference="ur5_ee_link">
    <selfCollide>true</selfCollide>
  </gazebo>
</robot>